<?xml version="1.0" ?>
<robot name="simple_robot" xmlns:xacro="http://www.ros.org/wiki/xacro">

<xacro:include filename="$(find simple_robot_description)/urdf/materials.xacro" />
<xacro:include filename="$(find simple_robot_description)/urdf/simple_robot.trans" />
<xacro:include filename="$(find simple_robot_description)/urdf/simple_robot.gazebo" />
<link name="base_link">
  <inertial>
    <origin xyz="-2.296521794040366e-15 0.0 0.049781352227497" rpy="0 0 0"/>
    <mass value="6.963815835528739"/>
    <inertia ixx="0.011301" iyy="0.011246" izz="0.0196" ixy="0.0" iyz="0.0" ixz="-0.0"/>
  </inertial>
  <visual>  
    <origin xyz="0 0 0" rpy="0 0 0"/>
    <geometry>
      <mesh filename="package://simple_robot_description/meshes/base_link.stl" scale="0.001 0.001 0.001"/>
    </geometry>
    <material name="steel_satin"/>
  </visual>
  <collision>
    <origin xyz="0 0 0" rpy="0 0 0"/>
    <geometry>
      <mesh filename="package://simple_robot_description/meshes/base_link.stl" scale="0.001 0.001 0.001"/>
    </geometry>
  </collision>
</link>

<link name="left_wheel">
  <inertial>
    <origin xyz="1.7474918813245557e-17 0.0025301810865191177 6.938893903907228e-18" rpy="0 0 0"/>
    <mass value="0.0234205732325119"/>
    <inertia ixx="1.6e-05" iyy="2.9e-05" izz="1.6e-05" ixy="0.0" iyz="0.0" ixz="0.0"/>
  </inertial>
  <visual>
    <origin xyz="-0.0 -0.09 -0.05" rpy="0 0 0"/>
    <geometry>
      <mesh filename="package://simple_robot_description/meshes/left_wheel_v3_1.stl" scale="0.001 0.001 0.001"/>
    </geometry>
    <material name="rubber_hard"/>
  </visual>
  <collision>
    <origin xyz="-0.0 -0.09 -0.05" rpy="0 0 0"/>
    <geometry>
      <mesh filename="package://simple_robot_description/meshes/left_wheel_v3_1.stl" scale="0.001 0.001 0.001"/>
    </geometry>
  </collision>
</link>

<link name="right_wheel">
  <inertial>
    <origin xyz="5.271600508662411e-15 -0.0025301810865191177 6.938893903907228e-18" rpy="0 0 0"/>
    <mass value="0.0234205732325119"/>
    <inertia ixx="1.6e-05" iyy="2.9e-05" izz="1.6e-05" ixy="-0.0" iyz="0.0" ixz="0.0"/>
  </inertial>
  <visual>
    <origin xyz="-0.0 0.09 -0.05" rpy="0 0 0"/>
    <geometry>
      <mesh filename="package://simple_robot_description/meshes/right_wheel_v3_1.stl" scale="0.001 0.001 0.001"/>
    </geometry>
    <material name="rubber_hard"/>
  </visual>
  <collision>
    <origin xyz="-0.0 0.09 -0.05" rpy="0 0 0"/>
    <geometry>
      <mesh filename="package://simple_robot_description/meshes/right_wheel_v3_1.stl" scale="0.001 0.001 0.001"/>
    </geometry>
  </collision>
</link>

<link name="ydlidar_x4">
  <inertial>
    <origin xyz="-0.021705900429680475 -1.015734249060124e-18 0.03520114222279104" rpy="0 0 0"/>
    <mass value="1.1515616542314233"/>
    <inertia ixx="0.000489" iyy="0.000861" izz="0.000987" ixy="-0.0" iyz="-0.0" ixz="0.000148"/>
  </inertial>
  <visual>
    <origin xyz="-0.0 -0.0 -0.075" rpy="0 0 0"/>
    <geometry>
      <mesh filename="package://simple_robot_description/meshes/ydlidar_x4_v1_1.stl" scale="0.001 0.001 0.001"/>
    </geometry>
    <material name="steel_satin"/>
  </visual>
  <collision>
    <origin xyz="-0.0 -0.0 -0.075" rpy="0 0 0"/>
    <geometry>
      <mesh filename="package://simple_robot_description/meshes/ydlidar_x4_v1_1.stl" scale="0.001 0.001 0.001"/>
    </geometry>
  </collision>
</link>

<link name="Intel_Realsense_D455">
  <inertial>
    <origin xyz="0.05789841470607983 -0.00015824044066372424 0.01543635795160929" rpy="0 0 0"/>
    <mass value="0.42243075146777714"/>
    <inertia ixx="0.000535" iyy="4.8e-05" izz="0.000526" ixy="0.0" iyz="0.0" ixz="-0.0"/>
  </inertial>
  <visual>
    <origin xyz="-0.0 -0.0 -0.075" rpy="0 0 0"/>
    <geometry>
      <mesh filename="package://simple_robot_description/meshes/Intel_Realsense_D455_v1_1.stl" scale="0.001 0.001 0.001"/>
    </geometry>
    <material name="silver_default"/>
  </visual>
  <collision>
    <origin xyz="-0.0 -0.0 -0.075" rpy="0 0 0"/>
    <geometry>
      <mesh filename="package://simple_robot_description/meshes/Intel_Realsense_D455_v1_1.stl" scale="0.001 0.001 0.001"/>
    </geometry>
  </collision>
</link>

<joint name="left_drive" type="continuous">
  <origin xyz="0.0 0.09 0.05" rpy="0 0 0"/>
  <parent link="base_link"/>
  <child link="left_wheel"/>
  <axis xyz="0.0 1.0 0.0"/>
</joint>

<!-- Remove the Negatibve sign in joint axis, else Teleop Keyboard wont work properly-->

<joint name="right_drive" type="continuous">
  <origin xyz="0.0 -0.09 0.05" rpy="0 0 0"/>
  <parent link="base_link"/>
  <child link="right_wheel"/>
  <axis xyz="0.0 1.0 0.0"/>
</joint>

<joint name="Rigid3" type="fixed">
  <origin xyz="0.0 0.0 0.075" rpy="0 0 0"/>
  <parent link="base_link"/>
  <child link="ydlidar_x4"/>
</joint>

<joint name="Rigid4" type="fixed">
  <origin xyz="0.0 0.0 0.075" rpy="0 0 0"/>
  <parent link="base_link"/>
  <child link="Intel_Realsense_D455"/>
</joint>

</robot>
